<mujoco model="ant">
  <compiler angle="degree" coordinate="global"/>
  <option integrator="RK4" timestep="0.01"/>
  <custom>
    <numeric data="0.0 0.0 0.55 1.0 0.0 0.0 0.0 0.0 1.0 0.0 -1.0 0.0 -1.0 0.0 1.0" name="init_qpos"/>
  </custom>
  <default>
    <joint armature="1" damping="1" limited="true"/>
    <geom conaffinity="0" condim="3" density="5.0" friction="1 0.5 0.5" margin="0.01" rgba="0.5 0.6 0.4 1"/>
  </default>
  <asset>
    <texture builtin="gradient" height="100" rgb1="1 1 1" rgb2="0 0 0" type="skybox" width="100"/>
    <texture builtin="flat" height="1278" mark="cross" markrgb="1 1 1" name="texgeom" random="0.01" rgb1="0.8 0.6 0.4" rgb2="0.8 0.6 0.4" type="cube" width="127"/>
    <texture builtin="checker" height="100" name="texplane" rgb1="0 0 0" rgb2="0.8 0.8 0.8" type="2d" width="100"/>
    <material name="MatPlane" reflectance="0.5" shininess="1" specular="1" texrepeat="60 60" texture="texplane"/>
    <material name="geom" texture="texgeom" texuniform="true"/>
  </asset>
  <worldbody>
    <light cutoff="100" diffuse="1 1 1" dir="-0 0 -1.3" directional="true" exponent="1" pos="0 0 1.3" specular=".1 .1 .1"/>
    <geom conaffinity="1" condim="3" material="MatPlane" name="floor" pos="0 0 0" rgba="0.8 0.9 0.8 1" size="40 40 40" type="plane"/>
    <body name="torso" pos="0 0 0.5">
      <inertial pos="0 0 0.5" mass="1" diaginertia="1 1 1"/>
      <camera name="track" mode="trackcom" pos="0 -3 0.3" xyaxes="1 0 0 0 0 1"/>
      <geom name="torso_geom" pos="0 0 0.5" size="0.25" type="sphere"/>
      <site name="torso" pos="0 0 0.5" size=".03 .03 .03" type="ellipsoid" rgba="1 0 0 1"/>
      <joint armature="0" damping="0" limited="false" margin="0.01" name="root" pos="0 0 0" type="free"/>
        <body name="leg1">
            <inertial pos="0.4 0 0.5" mass="1" diaginertia="1 1 1"/>
            <geom fromto="0.25 0 0.5 0.55 0 0.5" size="0.08" type="capsule"/>
            <body name="block">
                <inertial pos="1.13 0 0.5" mass="5" diaginertia="1 1 1"/>
                <joint type="hinge" pos="0.55 0 0.5" range="-90 90" axis="0 0 1"/>
                <geom type="box" size="0.5 0.5 0.5" pos="1.13 0 0.5"/>
            </body>
            <!--<joint axis="0 0 1" name="hip1" type="hinge" range="-60 60" pos="0.25 0 0.5"/>
            <body>
                <inertial pos="0.8 0 0.5" mass="1" diaginertia="1 1 1"/>
                <joint axis="0 -1 0" name="ankle1" type="hinge" range="-70 60" pos="0.55 0 0.5"/>
                <geom fromto="0.55 0.0 0.5 1.05 0.0 0.5" size="0.08" type="capsule"/>
                <body name="block">
                    <inertial pos="1.63 0 0.5" mass="2" diaginertia="1 1 1"/>
                    <joint type="hinge" pos="1.05 0 0.5" range="-90 90" axis="0 1 0"/>
                    <joint type="hinge" pos="1.05 0 0.5" range="-90 90" axis="1 0 0"/>
                    <joint type="hinge" pos="1.05 0 0.5" range="-90 90" axis="0 0 1"/>
                    <geom type="box" size="0.5 0.5 0.5" pos="1.63 0 0.5"/>
                </body>
            </body>-->
       </body>
        <body name="leg2">
            <inertial pos="-0.2 0.3464 0.5" mass="1" diaginertia="1 1 1"/>
            <joint axis="0 0 1" name="hip2" type="hinge" range="-30 30" pos="-0.125 0.2165 0.5"/>
            <geom fromto="-0.125 0.2165 0.5 -0.275 0.4763 0.5" size="0.08" type="capsule"/>
            <!--<inertial pos="-0.2 0.348 0.5" mass="3" diaginertia="1 1 1"/>-->
            <body>
                <inertial pos="-0.4 0.692815 0.5" mass="1" diaginertia="1 1 1"/>
                <joint axis="0.866025404 0.5 0" name="ankle2" type="hinge" range="-70 -30" pos="-0.275 0.4763 0.5"/>
                <geom fromto="-0.275 0.4763 0.5 -0.525 0.90933 0.5" size="0.08" type="capsule"/>
                <!--<inertial pos="-0.4 0.696 0.5" mass="2" diaginertia="1 1 1"/>-->
                <body pos="-0.565 0.9786 0.5">
                    <site name="foot2" pos="-0.565 0.9786 0.5" size=".03 .03 .03" type="ellipsoid" rgba="1 0 0 1"/>
                </body>
            </body>
        </body>
        <body name="leg3">
            <inertial pos="-0.2 -0.3464 0.5" mass="1" diaginertia="1 1 1"/>
            <joint axis="0 0 1" name="hip3" type="hinge" range="-30 30" pos="-0.125 -0.2165 0.5"/>
            <geom fromto="-0.125 -0.2165 0.5 -0.275 -0.4763 0.5" size="0.08" type="capsule"/>
            <body>
                <inertial pos="-0.4 -0.692815 0.5" mass="1" diaginertia="1 1 1"/>
                <joint axis="-0.866025404 0.5 0" name="ankle3" type="hinge" range="-70 -30" pos="-0.275 -0.4763 0.5"/>
                <geom fromto="-0.275 -0.4763 0.5 -0.525 -0.90933 0.5" size="0.08" type="capsule"/>
                <body pos="-0.565 -0.9786 0.5">                
                    <site name="foot3" pos="-0.565 -0.9786 0.5"/>
                </body>
            </body>
        </body>     
    </body>
  </worldbody>
  <sensor>
    <touch name="foot2Sensor" site="foot2" />
    <touch name="torsoSensor" site="torso" />
    <!-- <force site="foot2" name="foot2Sensor" noise="1.0" cutoff="100000"/> -->
    <!--<force site="foot3" name="foot3Sensor" noise="0" cutoff="100000"/>-->
  </sensor>
  <actuator>
    <!--<motor ctrllimited="true" ctrlrange="-1.0 1.0" joint="hip1" gear="150"/>
    <motor ctrllimited="true" ctrlrange="-1.0 1.0" joint="ankle1" gear="150"/>-->
    <motor ctrllimited="true" ctrlrange="-1.0 1.0" joint="hip2" gear="150"/>
    <motor ctrllimited="true" ctrlrange="-1.0 1.0" joint="ankle2" gear="150"/>
    <motor ctrllimited="true" ctrlrange="-1.0 1.0" joint="hip3" gear="150"/>
    <motor ctrllimited="true" ctrlrange="-1.0 1.0" joint="ankle3" gear="150"/>
  </actuator>
</mujoco>

